Workbook

Sheet movies
A1: movie_id | B1: Column2 | C1: Column3 | D1: release_year | E1: imdb_rating | F1: trim fn | G1: studio | H1: language_id | I1: BUDGET | J1: BUDGET2 | K1: budget3 | L1: revenue | M1: unit | N1: currency | O1: Column4 | P1: budget4 | Q1: revenue2 | R1: unit2 | S1: currency2 | T1: currency22 | U1: revenue3 | V1: budget5 | W1: unit3 | X1: currency3 | Y1: budget(mln) | Z1: revenue(mln) | AA1: budget(usd) | AB1: revenue(usd)
A2: 101 | B2: K.G.F | C2: Chapter 2 | D2: 2022 | E2: 8.4 | F2: =TRIM(Movies[[#This Row],[studio]]) -> Hombale Films | G2: Hombale Films | H2: 3 | I2: =INDEX(financials!B:B,MATCH(VALUE(LEFT(Movies[[#This Row],[movie_id]],3)),financials!A:A,0)) -> 1 | J2: =VLOOKUP(Movies[[#This Row],[movie_id]],financials!A:C,2,FALSE) -> 1 | K2: =INDEX(financials!B:B,MATCH(Movies[[#This Row],[movie_id]],financials!A:A,0)) -> 1 | L2: =INDEX(financials!C:C,MATCH(Movies[[#This Row],[movie_id]],financials!A:A,0)) -> 12.5 | M2: =INDEX(financials!D:D,MATCH(Movies[[#This Row],[movie_id]],financials!A:A,0)) -> Billions | N2: =INDEX(financials!E:E,MATCH(Movies[[#This Row],[movie_id]],financials!A:A,0)) -> INR | P2: =INDEX(Financials[],MATCH(Movies[[#This Row],[movie_id]:[movie_id]],Financials[[movie_id]:[movie_id]],0),MATCH("budget",Financials[#Headers],0)) -> 1 | Q2: =INDEX(Financials[],MATCH(Movies[[#This Row],[movie_id]:[movie_id]],Financials[[movie_id]:[movie_id]],0),MATCH("revenue",Financials[#Headers],0)) -> 12.5 | R2: =INDEX(Financials[],MATCH(Movies[[#This Row],[movie_id]:[movie_id]],Financials[[movie_id]:[movie_id]],0),MATCH("unit",Financials[#Headers],0)) -> Billions | S2: =INDEX(Financials[],MATCH(Movies[[#This Row],[movie_id]:[movie_id]],Financials[[movie_id]:[movie_id]],0),MATCH("currency",Financials[#Headers],0)) -> INR | U2: =INDEX(financials!$A:$D,MATCH(Movies[[#This Row],[movie_id]],financials!$A:$A,0), MATCH("revenue",financials!$1:$1,0)) -> 12.5 | V2: =INDEX(financials!$A:$D,MATCH(Movies[[#This Row],[movie_id]],financials!$A:$A,0), MATCH("budget",financials!$1:$1,0)) -> 1 | W2: =INDEX(financials!$A:$D,MATCH(Movies[[#This Row],[movie_id]],financials!$A:$A,0), MATCH("unit",financials!$1:$1,0)) -> Billions | X2: =INDEX(financials!$A:$D,MATCH(Movies[[#This Row],[movie_id]],financials!$A:$A,0), MATCH("currency",financials!$1:$1,0)) -> #REF! | Y2: =IF(Movies[[#This Row],[unit3]]="Billions",Movies[[#This Row],[budget5]]*1000,Movies[[#This Row],[budget5]]) -> 1000 | Z2: =IF(Movies[[#This Row],[unit3]]="Billions",Movies[[#This Row],[revenue3]]*1000,Movies[[#This Row],[revenue3]]) -> 12500 | AA2: =IF(Movies[[#This Row],[currency2]]="INR",Movies[[#This Row],[budget(mln)]]/92,Movies[[#This Row],[budget(mln)]]) -> 10.869565 | AB2: =IF(Movies[[#This Row],[currency2]]="INR",Movies[[#This Row],[revenue(mln)]]/92,Movies[[#This Row],[revenue(mln)]]) -> 135.86957
A3: 102 | B3: Doctor Strange in the Multiverse of Madness | D3: 2022 | E3: 7 | F3: =TRIM(Movies[[#This Row],[studio]]) -> Marvel Studios | G3: Marvel Studios | H3: 5 | I3: =INDEX(financials!B:B,MATCH(VALUE(LEFT(Movies[[#This Row],[movie_id]],3)),financials!A:A,0)) -> 200 | J3: =VLOOKUP(Movies[[#This Row],[movie_id]],financials!A:C,2,FALSE) -> 200 | K3: =INDEX(financials!B:B,MATCH(Movies[[#This Row],[movie_id]],financials!A:A,0)) -> 200 | L3: =INDEX(financials!C:C,MATCH(Movies[[#This Row],[movie_id]],financials!A:A,0)) -> 954.8 | M3: =INDEX(financials!D:D,MATCH(Movies[[#This Row],[movie_id]],financials!A:A,0)) -> Millions | N3: =INDEX(financials!E:E,MATCH(Movies[[#This Row],[movie_id]],financials!A:A,0)) -> USD | P3: =INDEX(Financials[],MATCH(Movies[[#This Row],[movie_id]:[movie_id]],Financials[[movie_id]:[movie_id]],0),MATCH("budget",Financials[#Headers],0)) -> 200 | Q3: =INDEX(Financials[],MATCH(Movies[[#This Row],[movie_id]:[movie_id]],Financials[[movie_id]:[movie_id]],0),MATCH("revenue",Financials[#Headers],0)) -> 954.8 | R3: =INDEX(Financials[],MATCH(Movies[[#This Row],[movie_id]:[movie_id]],Financials[[movie_id]:[movie_id]],0),MATCH("unit",Financials[#Headers],0)) -> Millions | S3: =INDEX(Financials[],MATCH(Movies[[#This Row],[movie_id]:[movie_id]],Financials[[movie_id]:[movie_id]],0),MATCH("currency",Financials[#Headers],0)) -> USD | U3: =INDEX(financials!$A:$D,MATCH(Movies[[#This Row],[movie_id]],financials!$A:$A,0), MATCH("revenue",financials!$1:$1,0)) -> 954.8 | V3: =INDEX(financials!$A:$D,MATCH(Movies[[#This Row],[movie_id]],financials!$A:$A,0), MATCH("budget",financials!$1:$1,0)) -> 200 | W3: =INDEX(financials!$A:$D,MATCH(Movies[[#This Row],[movie_id]],financials!$A:$A,0), MATCH("unit",financials!$1:$1,0)) -> Millions | X3: =INDEX(financials!$A:$D,MATCH(Movies[[#This Row],[movie_id]],financials!$A:$A,0), MATCH("currency",financials!$1:$1,0)) -> #REF! | Y3: =IF(Movies[[#This Row],[unit3]]="Billions",Movies[[#This Row],[budget5]]*1000,Movies[[#This Row],[budget5]]) -> 200 | Z3: =IF(Movies[[#This Row],[unit3]]="Billions",Movies[[#This Row],[revenue3]]*1000,Movies[[#This Row],[revenue3]]) -> 954.8 | AA3: =IF(Movies[[#This Row],[currency2]]="INR",Movies[[#This Row],[budget(mln)]]/92,Movies[[#This Row],[budget(mln)]]) -> 200 | AB3: =IF(Movies[[#This Row],[currency2]]="INR",Movies[[#This Row],[revenue(mln)]]/92,Movies[[#This Row],[revenue(mln)]]) -> 954.8
A4: 103 | B4: Thor | C4: The Dark World | D4: 2013 | E4: 6.8 | F4: =TRIM(Movies[[#This Row],[studio]]) -> Marvel Studios | G4: Marvel Studios | H4: 5 | I4: =INDEX(financials!B:B,MATCH(VALUE(LEFT(Movies[[#This Row],[movie_id]],3)),financials!A:A,0)) -> 165 | J4: =VLOOKUP(Movies[[#This Row],[movie_id]],financials!A:C,2,FALSE) -> 165 | K4: =INDEX(financials!B:B,MATCH(Movies[[#This Row],[movie_id]],financials!A:A,0)) -> 165 | L4: =INDEX(financials!C:C,MATCH(Movies[[#This Row],[movie_id]],financials!A:A,0)) -> 644.8 | M4: =INDEX(financials!D:D,MATCH(Movies[[#This Row],[movie_id]],financials!A:A,0)) -> Millions | N4: =INDEX(financials!E:E,MATCH(Movies[[#This Row],[movie_id]],financials!A:A,0)) -> USD | P4: =INDEX(Financials[],MATCH(Movies[[#This Row],[movie_id]:[movie_id]],Financials[[movie_id]:[movie_id]],0),MATCH("budget",Financials[#Headers],0)) -> 165 | Q4: =INDEX(Financials[],MATCH(Movies[[#This Row],[movie_id]:[movie_id]],Financials[[movie_id]:[movie_id]],0),MATCH("revenue",Financials[#Headers],0)) -> 644.8 | R4: =INDEX(Financials[],MATCH(Movies[[#This Row],[movie_id]:[movie_id]],Financials[[movie_id]:[movie_id]],0),MATCH("unit",Financials[#Headers],0)) -> Millions | S4: =INDEX(Financials[],MATCH(Movies[[#This Row],[movie_id]:[movie_id]],Financials[[movie_id]:[movie_id]],0),MATCH("currency",Financials[#Headers],0)) -> USD | U4: =INDEX(financials!$A:$D,MATCH(Movies[[#This Row],[movie_id]],financials!$A:$A,0), MATCH("revenue",financials!$1:$1,0)) -> 644.8 | V4: =INDEX(financials!$A:$D,MATCH(Movies[[#This Row],[movie_id]],financials!$A:$A,0), MATCH("budget",financials!$1:$1,0)) -> 165 | W4: =INDEX(financials!$A:$D,MATCH(Movies[[#This Row],[movie_id]],financials!$A:$A,0), MATCH("unit",financials!$1:$1,0)) -> Millions | X4: =INDEX(financials!$A:$D,MATCH(Movies[[#This Row],[movie_id]],financials!$A:$A,0), MATCH("currency",financials!$1:$1,0)) -> #REF! | Y4: =IF(Movies[[#This Row],[unit3]]="Billions",Movies[[#This Row],[budget5]]*1000,Movies[[#This Row],[budget5]]) -> 165 | Z4: =IF(Movies[[#This Row],[unit3]]="Billions",Movies[[#This Row],[revenue3]]*1000,Movies[[#This Row],[revenue3]]) -> 644.8 | AA4: =IF(Movies[[#This Row],[currency2]]="INR",Movies[[#This Row],[budget(mln)]]/92,Movies[[#This Row],[budget(mln)]]) -> 165 | AB4: =IF(Movies[[#This Row],[currency2]]="INR",Movies[[#This Row],[revenue(mln)]]/92,Movies[[#This Row],[revenue(mln)]]) -> 644.8
A5: 104 | B5: Thor | C5: Ragnarok | D5: 2017 | E5: 7.9 | F5: =TRIM(Movies[[#This Row],[studio]]) -> Marvel Studios | G5: Marvel Studios | H5: 5 | I5: =INDEX(financials!B:B,MATCH(VALUE(LEFT(Movies[[#This Row],[movie_id]],3)),financials!A:A,0)) -> 180 | J5: =VLOOKUP(Movies[[#This Row],[movie_id]],financials!A:C,2,FALSE) -> 180 | K5: =INDEX(financials!B:B,MATCH(Movies[[#This Row],[movie_id]],financials!A:A,0)) -> 180 | L5: =INDEX(financials!C:C,MATCH(Movies[[#This Row],[movie_id]],financials!A:A,0)) -> 854 | M5: =INDEX(financials!D:D,MATCH(Movies[[#This Row],[movie_id]],financials!A:A,0)) -> Millions | N5: =INDEX(financials!E:E,MATCH(Movies[[#This Row],[movie_id]],financials!A:A,0)) -> USD | P5: =INDEX(Financials[],MATCH(Movies[[#This Row],[movie_id]:[movie_id]],Financials[[movie_id]:[movie_id]],0),MATCH("budget",Financials[#Headers],0)) -> 180 | Q5: =INDEX(Financials[],MATCH(Movies[[#This Row],[movie_id]:[movie_id]],Financials[[movie_id]:[movie_id]],0),MATCH("revenue",Financials[#Headers],0)) -> 854 | R5: =INDEX(Financials[],MATCH(Movies[[#This Row],[movie_id]:[movie_id]],Financials[[movie_id]:[movie_id]],0),MATCH("unit",Financials[#Headers],0)) -> Millions | S5: =INDEX(Financials[],MATCH(Movies[[#This Row],[movie_id]:[movie_id]],Financials[[movie_id]:[movie_id]],0),MATCH("currency",Financials[#Headers],0)) -> USD | U5: =INDEX(financials!$A:$D,MATCH(Movies[[#This Row],[movie_id]],financials!$A:$A,0), MATCH("revenue",financials!$1:$1,0)) -> 854 | V5: =INDEX(financials!$A:$D,MATCH(Movies[[#This Row],[movie_id]],financials!$A:$A,0), MATCH("budget",financials!$1:$1,0)) -> 180 | W5: =INDEX(financials!$A:$D,MATCH(Movies[[#This Row],[movie_id]],financials!$A:$A,0), MATCH("unit",financials!$1:$1,0)) -> Millions | X5: =INDEX(financials!$A:$D,MATCH(Movies[[#This Row],[movie_id]],financials!$A:$A,0), MATCH("currency",financials!$1:$1,0)) -> #REF! | Y5: =IF(Movies[[#This Row],[unit3]]="Billions",Movies[[#This Row],[budget5]]*1000,Movies[[#This Row],[budget5]]) -> 180 | Z5: =IF(Movies[[#This Row],[unit3]]="Billions",Movies[[#This Row],[revenue3]]*1000,Movies[[#This Row],[revenue3]]) -> 854 | AA5: =IF(Movies[[#This Row],[currency2]]="INR",Movies[[#This Row],[budget(mln)]]/92,Movies[[#This Row],[budget(mln)]]) -> 180 | AB5: =IF(Movies[[#This Row],[currency2]]="INR",Movies[[#This Row],[revenue(mln)]]/92,Movies[[#This Row],[revenue(mln)]]) -> 854
A6: 105 | B6: Thor | C6: Love and Thunder | D6: 2022 | E6: 6.8 | F6: =TRIM(Movies[[#This Row],[studio]]) -> Marvel Studios | G6: Marvel Studios | H6: 5 | I6: =INDEX(financials!B:B,MATCH(VALUE(LEFT(Movies[[#This Row],[movie_id]],3)),financials!A:A,0)) -> 250 | J6: =VLOOKUP(Movies[[#This Row],[movie_id]],financials!A:C,2,FALSE) -> 250 | K6: =INDEX(financials!B:B,MATCH(Movies[[#This Row],[movie_id]],financials!A:A,0)) -> 250 | L6: =INDEX(financials!C:C,MATCH(Movies[[#This Row],[movie_id]],financials!A:A,0)) -> 670 | M6: =INDEX(financials!D:D,MATCH(Movies[[#This Row],[movie_id]],financials!A:A,0)) -> Millions | N6: =INDEX(financials!E:E,MATCH(Movies[[#This Row],[movie_id]],financials!A:A,0)) -> USD | P6: =INDEX(Financials[],MATCH(Movies[[#This Row],[movie_id]:[movie_id]],Financials[[movie_id]:[movie_id]],0),MATCH("budget",Financials[#Headers],0)) -> 250 | Q6: =INDEX(Financials[],MATCH(Movies[[#This Row],[movie_id]:[movie_id]],Financials[[movie_id]:[movie_id]],0),MATCH("revenue",Financials[#Headers],0)) -> 670 | R6: =INDEX(Financials[],MATCH(Movies[[#This Row],[movie_id]:[movie_id]],Financials[[movie_id]:[movie_id]],0),MATCH("unit",Financials[#Headers],0)) -> Millions | S6: =INDEX(Financials[],MATCH(Movies[[#This Row],[movie_id]:[movie_id]],Financials[[movie_id]:[movie_id]],0),MATCH("currency",Financials[#Headers],0)) -> USD | U6: =INDEX(financials!$A:$D,MATCH(Movies[[#This Row],[movie_id]],financials!$A:$A,0), MATCH("revenue",financials!$1:$1,0)) -> 670 | V6: =INDEX(financials!$A:$D,MATCH(Movies[[#This Row],[movie_id]],financials!$A:$A,0), MATCH("budget",financials!$1:$1,0)) -> 250 | W6: =INDEX(financials!$A:$D,MATCH(Movies[[#This Row],[movie_id]],financials!$A:$A,0), MATCH("unit",financials!$1:$1,0)) -> Millions | X6: =INDEX(financials!$A:$D,MATCH(Movies[[#This Row],[movie_id]],financials!$A:$A,0), MATCH("currency",financials!$1:$1,0)) -> #REF! | Y6: =IF(Movies[[#This Row],[unit3]]="Billions",Movies[[#This Row],[budget5]]*1000,Movies[[#This Row],[budget5]]) -> 250 | Z6: =IF(Movies[[#This Row],[unit3]]="Billions",Movies[[#This Row],[revenue3]]*1000,Movies[[#This Row],[revenue3]]) -> 670 | AA6: =IF(Movies[[#This Row],[currency2]]="INR",Movies[[#This Row],[budget(mln)]]/92,Movies[[#This Row],[budget(mln)]]) -> 250 | AB6: =IF(Movies[[#This Row],[currency2]]="INR",Movies[[#This Row],[revenue(mln)]]/92,Movies[[#This Row],[revenue(mln)]]) -> 670
A7: 107 | B7: Dilwale Dulhania Le Jayenge | D7: 1995 | E7: 8 | F7: =TRIM(Movies[[#This Row],[studio]]) -> Yash Raj Films | G7: Yash Raj Films | H7: 1 | I7: =INDEX(financials!B:B,MATCH(VALUE(LEFT(Movies[[#This Row],[movie_id]],3)),financials!A:A,0)) -> 400 | J7: =VLOOKUP(Movies[[#This Row],[movie_id]],financials!A:C,2,FALSE) -> 400 | K7: =INDEX(financials!B:B,MATCH(Movies[[#This Row],[movie_id]],financials!A:A,0)) -> 400 | L7: =INDEX(financials!C:C,MATCH(Movies[[#This Row],[movie_id]],financials!A:A,0)) -> 2000 | M7: =INDEX(financials!D:D,MATCH(Movies[[#This Row],[movie_id]],financials!A:A,0)) -> Millions | N7: =INDEX(financials!E:E,MATCH(Movies[[#This Row],[movie_id]],financials!A:A,0)) -> INR | P7: =INDEX(Financials[],MATCH(Movies[[#This Row],[movie_id]:[movie_id]],Financials[[movie_id]:[movie_id]],0),MATCH("budget",Financials[#Headers],0)) -> 400 | Q7: =INDEX(Financials[],MATCH(Movies[[#This Row],[movie_id]:[movie_id]],Financials[[movie_id]:[movie_id]],0),MATCH("revenue",Financials[#Headers],0)) -> 2000 | R7: =INDEX(Financials[],MATCH(Movies[[#This Row],[movie_id]:[movie_id]],Financials[[movie_id]:[movie_id]],0),MATCH("unit",Financials[#Headers],0)) -> Millions | S7: =INDEX(Financials[],MATCH(Movies[[#This Row],[movie_id]:[movie_id]],Financials[[movie_id]:[movie_id]],0),MATCH("currency",Financials[#Headers],0)) -> INR | U7: =INDEX(financials!$A:$D,MATCH(Movies[[#This Row],[movie_id]],financials!$A:$A,0), MATCH("revenue",financials!$1:$1,0)) -> 2000 | V7: =INDEX(financials!$A:$D,MATCH(Movies[[#This Row],[movie_id]],financials!$A:$A,0), MATCH("budget",financials!$1:$1,0)) -> 400 | W7: =INDEX(financials!$A:$D,MATCH(Movies[[#This Row],[movie_id]],financials!$A:$A,0), MATCH("unit",financials!$1:$1,0)) -> Millions | X7: =INDEX(financials!$A:$D,MATCH(Movies[[#This Row],[movie_id]],financials!$A:$A,0), MATCH("currency",financials!$1:$1,0)) -> #REF! | Y7: =IF(Movies[[#This Row],[unit3]]="Billions",Movies[[#This Row],[budget5]]*1000,Movies[[#This Row],[budget5]]) -> 400 | Z7: =IF(Movies[[#This Row],[unit3]]="Billions",Movies[[#This Row],[revenue3]]*1000,Movies[[#This Row],[revenue3]]) -> 2000 | AA7: =IF(Movies[[#This Row],[currency2]]="INR",Movies[[#This Row],[budget(mln)]]/92,Movies[[#This Row],[budget(mln)]]) -> 4.3478261 | AB7: =IF(Movies[[#This Row],[currency2]]="INR",Movies[[#This Row],[revenue(mln)]]/92,Movies[[#This Row],[revenue(mln)]]) -> 21.73913
A8: 108 | B8: 3 Idiots | D8: 2009 | E8: 8.4 | F8: =TRIM(Movies[[#This Row],[studio]]) -> Vinod Chopra Films | G8: Vinod Chopra Films | H8: 1 | I8: =INDEX(financials!B:B,MATCH(VALUE(LEFT(Movies[[#This Row],[movie_id]],3)),financials!A:A,0)) -> 550 | J8: =VLOOKUP(Movies[[#This Row],[movie_id]],financials!A:C,2,FALSE) -> 550 | K8: =INDEX(financials!B:B,MATCH(Movies[[#This Row],[movie_id]],financials!A:A,0)) -> 550 | L8: =INDEX(financials!C:C,MATCH(Movies[[#This Row],[movie_id]],financials!A:A,0)) -> 4000 | M8: =INDEX(financials!D:D,MATCH(Movies[[#This Row],[movie_id]],financials!A:A,0)) -> Millions | N8: =INDEX(financials!E:E,MATCH(Movies[[#This Row],[movie_id]],financials!A:A,0)) -> INR | P8: =INDEX(Financials[],MATCH(Movies[[#This Row],[movie_id]:[movie_id]],Financials[[movie_id]:[movie_id]],0),MATCH("budget",Financials[#Headers],0)) -> 550 | Q8: =INDEX(Financials[],MATCH(Movies[[#This Row],[movie_id]:[movie_id]],Financials[[movie_id]:[movie_id]],0),MATCH("revenue",Financials[#Headers],0)) -> 4000 | R8: =INDEX(Financials[],MATCH(Movies[[#This Row],[movie_id]:[movie_id]],Financials[[movie_id]:[movie_id]],0),MATCH("unit",Financials[#Headers],0)) -> Millions | S8: =INDEX(Financials[],MATCH(Movies[[#This Row],[movie_id]:[movie_id]],Financials[[movie_id]:[movie_id]],0),MATCH("currency",Financials[#Headers],0)) -> INR | U8: =INDEX(financials!$A:$D,MATCH(Movies[[#This Row],[movie_id]],financials!$A:$A,0), MATCH("revenue",financials!$1:$1,0)) -> 4000 | V8: =INDEX(financials!$A:$D,MATCH(Movies[[#This Row],[movie_id]],financials!$A:$A,0), MATCH("budget",financials!$1:$1,0)) -> 550 | W8: =INDEX(financials!$A:$D,MATCH(Movies[[#This Row],[movie_id]],financials!$A:$A,0), MATCH("unit",financials!$1:$1,0)) -> Millions | X8: =INDEX(financials!$A:$D,MATCH(Movies[[#This Row],[movie_id]],financials!$A:$A,0), MATCH("currency",financials!$1:$1,0)) -> #REF! | Y8: =IF(Movies[[#This Row],[unit3]]="Billions",Movies[[#This Row],[budget5]]*1000,Movies[[#This Row],[budget5]]) -> 550 | Z8: =IF(Movies[[#This Row],[unit3]]="Billions",Movies[[#This Row],[revenue3]]*1000,Movies[[#This Row],[revenue3]]) -> 4000 | AA8: =IF(Movies[[#This Row],[currency2]]="INR",Movies[[#This Row],[budget(mln)]]/92,Movies[[#This Row],[budget(mln)]]) -> 5.9782609 | AB8: =IF(Movies[[#This Row],[currency2]]="INR",Movies[[#This Row],[revenue(mln)]]/92,Movies[[#This Row],[revenue(mln)]]) -> 43.478261
A9: 109 | B9: Kabhi Khushi Kabhie Gham | D9: 2001 | E9: 7.4 | F9: =TRIM(Movies[[#This Row],[studio]]) -> Dharma Productions | G9: Dharma Productions | H9: 1 | I9: =INDEX(financials!B:B,MATCH(VALUE(LEFT(Movies[[#This Row],[movie_id]],3)),financials!A:A,0)) -> 390 | J9: =VLOOKUP(Movies[[#This Row],[movie_id]],financials!A:C,2,FALSE) -> 390 | K9: =INDEX(financials!B:B,MATCH(Movies[[#This Row],[movie_id]],financials!A:A,0)) -> 390 | L9: =INDEX(financials!C:C,MATCH(Movies[[#This Row],[movie_id]],financials!A:A,0)) -> 1360 | M9: =INDEX(financials!D:D,MATCH(Movies[[#This Row],[movie_id]],financials!A:A,0)) -> Millions | N9: =INDEX(financials!E:E,MATCH(Movies[[#This Row],[movie_id]],financials!A:A,0)) -> INR | P9: =INDEX(Financials[],MATCH(Movies[[#This Row],[movie_id]:[movie_id]],Financials[[movie_id]:[movie_id]],0),MATCH("budget",Financials[#Headers],0)) -> 390 | Q9: =INDEX(Financials[],MATCH(Movies[[#This Row],[movie_id]:[movie_id]],Financials[[movie_id]:[movie_id]],0),MATCH("revenue",Financials[#Headers],0)) -> 1360 | R9: =INDEX(Financials[],MATCH(Movies[[#This Row],[movie_id]:[movie_id]],Financials[[movie_id]:[movie_id]],0),MATCH("unit",Financials[#Headers],0)) -> Millions | S9: =INDEX(Financials[],MATCH(Movies[[#This Row],[movie_id]:[movie_id]],Financials[[movie_id]:[movie_id]],0),MATCH("currency",Financials[#Headers],0)) -> INR | U9: =INDEX(financials!$A:$D,MATCH(Movies[[#This Row],[movie_id]],financials!$A:$A,0), MATCH("revenue",financials!$1:$1,0)) -> 1360 | V9: =INDEX(financials!$A:$D,MATCH(Movies[[#This Row],[movie_id]],financials!$A:$A,0), MATCH("budget",financials!$1:$1,0)) -> 390 | W9: =INDEX(financials!$A:$D,MATCH(Movies[[#This Row],[movie_id]],financials!$A:$A,0), MATCH("unit",financials!$1:$1,0)) -> Millions | X9: =INDEX(financials!$A:$D,MATCH(Movies[[#This Row],[movie_id]],financials!$A:$A,0), MATCH("currency",financials!$1:$1,0)) -> #REF! | Y9: =IF(Movies[[#This Row],[unit3]]="Billions",Movies[[#This Row],[budget5]]*1000,Movies[[#This Row],[budget5]]) -> 390 | Z9: =IF(Movies[[#This Row],[unit3]]="Billions",Movies[[#This Row],[revenue3]]*1000,Movies[[#This Row],[revenue3]]) -> 1360 | AA9: =IF(Movies[[#This Row],[currency2]]="INR",Movies[[#This Row],[budget(mln)]]/92,Movies[[#This Row],[budget(mln)]]) -> 4.2391304 | AB9: =IF(Movies[[#This Row],[currency2]]="INR",Movies[[#This Row],[revenue(mln)]]/92,Movies[[#This Row],[revenue(mln)]]) -> 14.782609
A10: 110 | B10: Bajirao Mastani | D10: 2015 | E10: 7.2 | F10: =TRIM(Movies[[#This Row],[studio]]) | H10: 1 | I10: =INDEX(financials!B:B,MATCH(VALUE(LEFT(Movies[[#This Row],[movie_id]],3)),financials!A:A,0)) -> 1.4 | J10: =VLOOKUP(Movies[[#This Row],[movie_id]],financials!A:C,2,FALSE) -> 1.4 | K10: =INDEX(financials!B:B,MATCH(Movies[[#This Row],[movie_id]],financials!A:A,0)) -> 1.4 | L10: =INDEX(financials!C:C,MATCH(Movies[[#This Row],[movie_id]],financials!A:A,0)) -> 3.5 | M10: =INDEX(financials!D:D,MATCH(Movies[[#This Row],[movie_id]],financials!A:A,0)) -> Billions | N10: =INDEX(financials!E:E,MATCH(Movies[[#This Row],[movie_id]],financials!A:A,0)) -> INR | P10: =INDEX(Financials[],MATCH(Movies[[#This Row],[movie_id]:[movie_id]],Financials[[movie_id]:[movie_id]],0),MATCH("budget",Financials[#Headers],0)) -> 1.4 | Q10: =INDEX(Financials[],MATCH(Movies[[#This Row],[movie_id]:[movie_id]],Financials[[movie_id]:[movie_id]],0),MATCH("revenue",Financials[#Headers],0)) -> 3.5 | R10: =INDEX(Financials[],MATCH(Movies[[#This Row],[movie_id]:[movie_id]],Financials[[movie_id]:[movie_id]],0),MATCH("unit",Financials[#Headers],0)) -> Billions | S10: =INDEX(Financials[],MATCH(Movies[[#This Row],[movie_id]:[movie_id]],Financials[[movie_id]:[movie_id]],0),MATCH("currency",Financials[#Headers],0)) -> INR | U10: =INDEX(financials!$A:$D,MATCH(Movies[[#This Row],[movie_id]],financials!$A:$A,0), MATCH("revenue",financials!$1:$1,0)) -> 3.5 | V10: =INDEX(financials!$A:$D,MATCH(Movies[[#This Row],[movie_id]],financials!$A:$A,0), MATCH("budget",financials!$1:$1,0)) -> 1.4 | W10: =INDEX(financials!$A:$D,MATCH(Movies[[#This Row],[movie_id]],financials!$A:$A,0), MATCH("unit",financials!$1:$1,0)) -> Billions | X10: =INDEX(financials!$A:$D,MATCH(Movies[[#This Row],[movie_id]],financials!$A:$A,0), MATCH("currency",financials!$1:$1,0)) -> #REF! | Y10: =IF(Movies[[#This Row],[unit3]]="Billions",Movies[[#This Row],[budget5]]*1000,Movies[[#This Row],[budget5]]) -> 1400 | Z10: =IF(Movies[[#This Row],[unit3]]="Billions",Movies[[#This Row],[revenue3]]*1000,Movies[[#This Row],[revenue3]]) -> 3500 | AA10: =IF(Movies[[#This Row],[currency2]]="INR",Movies[[#This Row],[budget(mln)]]/92,Movies[[#This Row],[budget(mln)]]) -> 15.217391 | AB10: =IF(Movies[[#This Row],[currency2]]="INR",Movies[[#This Row],[revenue(mln)]]/92,Movies[[#This Row],[revenue(mln)]]) -> 38.043478
A11: 111 | B11: The Shawshank Redemption | D11: 1994 | E11: 9.3 | F11: =TRIM(Movies[[#This Row],[studio]]) -> Castle Rock Entertainment | G11: Castle Rock Entertainment | H11: 5 | I11: =INDEX(financials!B:B,MATCH(VALUE(LEFT(Movies[[#This Row],[movie_id]],3)),financials!A:A,0)) -> 25 | J11: =VLOOKUP(Movies[[#This Row],[movie_id]],financials!A:C,2,FALSE) -> 25 | K11: =INDEX(financials!B:B,MATCH(Movies[[#This Row],[movie_id]],financials!A:A,0)) -> 25 | L11: =INDEX(financials!C:C,MATCH(Movies[[#This Row],[movie_id]],financials!A:A,0)) -> 73.3 | M11: =INDEX(financials!D:D,MATCH(Movies[[#This Row],[movie_id]],financials!A:A,0)) -> Millions | N11: =INDEX(financials!E:E,MATCH(Movies[[#This Row],[movie_id]],financials!A:A,0)) -> USD | P11: =INDEX(Financials[],MATCH(Movies[[#This Row],[movie_id]:[movie_id]],Financials[[movie_id]:[movie_id]],0),MATCH("budget",Financials[#Headers],0)) -> 25 | Q11: =INDEX(Financials[],MATCH(Movies[[#This Row],[movie_id]:[movie_id]],Financials[[movie_id]:[movie_id]],0),MATCH("revenue",Financials[#Headers],0)) -> 73.3 | R11: =INDEX(Financials[],MATCH(Movies[[#This Row],[movie_id]:[movie_id]],Financials[[movie_id]:[movie_id]],0),MATCH("unit",Financials[#Headers],0)) -> Millions | S11: =INDEX(Financials[],MATCH(Movies[[#This Row],[movie_id]:[movie_id]],Financials[[movie_id]:[movie_id]],0),MATCH("currency",Financials[#Headers],0)) -> USD | U11: =INDEX(financials!$A:$D,MATCH(Movies[[#This Row],[movie_id]],financials!$A:$A,0), MATCH("revenue",financials!$1:$1,0)) -> 73.3 | V11: =INDEX(financials!$A:$D,MATCH(Movies[[#This Row],[movie_id]],financials!$A:$A,0), MATCH("budget",financials!$1:$1,0)) -> 25 | W11: =INDEX(financials!$A:$D,MATCH(Movies[[#This Row],[movie_id]],financials!$A:$A,0), MATCH("unit",financials!$1:$1,0)) -> Millions | X11: =INDEX(financials!$A:$D,MATCH(Movies[[#This Row],[movie_id]],financials!$A:$A,0), MATCH("currency",financials!$1:$1,0)) -> #REF! | Y11: =IF(Movies[[#This Row],[unit3]]="Billions",Movies[[#This Row],[budget5]]*1000,Movies[[#This Row],[budget5]]) -> 25 | Z11: =IF(Movies[[#This Row],[unit3]]="Billions",Movies[[#This Row],[revenue3]]*1000,Movies[[#This Row],[revenue3]]) -> 73.3 | AA11: =IF(Movies[[#This Row],[currency2]]="INR",Movies[[#This Row],[budget(mln)]]/92,Movies[[#This Row],[budget(mln)]]) -> 25 | AB11: =IF(Movies[[#This Row],[currency2]]="INR",Movies[[#This Row],[revenue(mln)]]/92,Movies[[#This Row],[revenue(mln)]]) -> 73.3
A12: 113 | B12: Interstellar | D12: 2014 | E12: 8.6 | F12: =TRIM(Movies[[#This Row],[studio]]) -> Warner Bros. Pictures | G12: Warner Bros. Pictures | H12: 5 | I12: =INDEX(financials!B:B,MATCH(VALUE(LEFT(Movies[[#This Row],[movie_id]],3)),financials!A:A,0)) -> 165 | J12: =VLOOKUP(Movies[[#This Row],[movie_id]],financials!A:C,2,FALSE) -> 165 | K12: =INDEX(financials!B:B,MATCH(Movies[[#This Row],[movie_id]],financials!A:A,0)) -> 165 | L12: =INDEX(financials!C:C,MATCH(Movies[[#This Row],[movie_id]],financials!A:A,0)) -> 701.8 | M12: =INDEX(financials!D:D,MATCH(Movies[[#This Row],[movie_id]],financials!A:A,0)) -> Millions | N12: =INDEX(financials!E:E,MATCH(Movies[[#This Row],[movie_id]],financials!A:A,0)) -> USD | P12: =INDEX(Financials[],MATCH(Movies[[#This Row],[movie_id]:[movie_id]],Financials[[movie_id]:[movie_id]],0),MATCH("budget",Financials[#Headers],0)) -> 165 | Q12: =INDEX(Financials[],MATCH(Movies[[#This Row],[movie_id]:[movie_id]],Financials[[movie_id]:[movie_id]],0),MATCH("revenue",Financials[#Headers],0)) -> 701.8 | R12: =INDEX(Financials[],MATCH(Movies[[#This Row],[movie_id]:[movie_id]],Financials[[movie_id]:[movie_id]],0),MATCH("unit",Financials[#Headers],0)) -> Millions | S12: =INDEX(Financials[],MATCH(Movies[[#This Row],[movie_id]:[movie_id]],Financials[[movie_id]:[movie_id]],0),MATCH("currency",Financials[#Headers],0)) -> USD | U12: =INDEX(financials!$A:$D,MATCH(Movies[[#This Row],[movie_id]],financials!$A:$A,0), MATCH("revenue",financials!$1:$1,0)) -> 701.8 | V12: =INDEX(financials!$A:$D,MATCH(Movies[[#This Row],[movie_id]],financials!$A:$A,0), MATCH("budget",financials!$1:$1,0)) -> 165 | W12: =INDEX(financials!$A:$D,MATCH(Movies[[#This Row],[movie_id]],financials!$A:$A,0), MATCH("unit",financials!$1:$1,0)) -> Millions | X12: =INDEX(financials!$A:$D,MATCH(Movies[[#This Row],[movie_id]],financials!$A:$A,0), MATCH("currency",financials!$1:$1,0)) -> #REF! | Y12: =IF(Movies[[#This Row],[unit3]]="Billions",Movies[[#This Row],[budget5]]*1000,Movies[[#This Row],[budget5]]) -> 165 | Z12: =IF(Movies[[#This Row],[unit3]]="Billions",Movies[[#This Row],[revenue3]]*1000,Movies[[#This Row],[revenue3]]) -> 701.8 | AA12: =IF(Movies[[#This Row],[currency2]]="INR",Movies[[#This Row],[budget(mln)]]/92,Movies[[#This Row],[budget(mln)]]) -> 165 | AB12: =IF(Movies[[#This Row],[currency2]]="INR",Movies[[#This Row],[revenue(mln)]]/92,Movies[[#This Row],[revenue(mln)]]) -> 701.8
A13: 115 | B13: The Pursuit of Happyness | D13: 2006 | E13: 8 | F13: =TRIM(Movies[[#This Row],[studio]]) -> Columbia Pictures | G13: Columbia Pictures | H13: 5 | I13: =INDEX(financials!B:B,MATCH(VALUE(LEFT(Movies[[#This Row],[movie_id]],3)),financials!A:A,0)) -> 55 | J13: =VLOOKUP(Movies[[#This Row],[movie_id]],financials!A:C,2,FALSE) -> 55 | K13: =INDEX(financials!B:B,MATCH(Movies[[#This Row],[movie_id]],financials!A:A,0)) -> 55 | L13: =INDEX(financials!C:C,MATCH(Movies[[#This Row],[movie_id]],financials!A:A,0)) -> 307.1 | M13: =INDEX(financials!D:D,MATCH(Movies[[#This Row],[movie_id]],financials!A:A,0)) -> Millions | N13: =INDEX(financials!E:E,MATCH(Movies[[#This Row],[movie_id]],financials!A:A,0)) -> USD | P13: =INDEX(Financials[],MATCH(Movies[[#This Row],[movie_id]:[movie_id]],Financials[[movie_id]:[movie_id]],0),MATCH("budget",Financials[#Headers],0)) -> 55 | Q13: =INDEX(Financials[],MATCH(Movies[[#This Row],[movie_id]:[movie_id]],Financials[[movie_id]:[movie_id]],0),MATCH("revenue",Financials[#Headers],0)) -> 307.1 | R13: =INDEX(Financials[],MATCH(Movies[[#This Row],[movie_id]:[movie_id]],Financials[[movie_id]:[movie_id]],0),MATCH("unit",Financials[#Headers],0)) -> Millions | S13: =INDEX(Financials[],MATCH(Movies[[#This Row],[movie_id]:[movie_id]],Financials[[movie_id]:[movie_id]],0),MATCH("currency",Financials[#Headers],0)) -> USD | U13: =INDEX(financials!$A:$D,MATCH(Movies[[#This Row],[movie_id]],financials!$A:$A,0), MATCH("revenue",financials!$1:$1,0)) -> 307.1 | V13: =INDEX(financials!$A:$D,MATCH(Movies[[#This Row],[movie_id]],financials!$A:$A,0), MATCH("budget",financials!$1:$1,0)) -> 55 | W13: =INDEX(financials!$A:$D,MATCH(Movies[[#This Row],[movie_id]],financials!$A:$A,0), MATCH("unit",financials!$1:$1,0)) -> Millions | X13: =INDEX(financials!$A:$D,MATCH(Movies[[#This Row],[movie_id]],financials!$A:$A,0), MATCH("currency",financials!$1:$1,0)) -> #REF! | Y13: =IF(Movies[[#This Row],[unit3]]="Billions",Movies[[#This Row],[budget5]]*1000,Movies[[#This Row],[budget5]]) -> 55 | Z13: =IF(Movies[[#This Row],[unit3]]="Billions",Movies[[#This Row],[revenue3]]*1000,Movies[[#This Row],[revenue3]]) -> 307.1 | AA13: =IF(Movies[[#This Row],[currency2]]="INR",Movies[[#This Row],[budget(mln)]]/92,Movies[[#This Row],[budget(mln)]]) -> 55 | AB13: =IF(Movies[[#This Row],[currency2]]="INR",Movies[[#This Row],[revenue(mln)]]/92,Movies[[#This Row],[revenue(mln)]]) -> 307.1
A14: 116 | B14: Gladiator | D14: 2000 | E14: 8.5 | F14: =TRIM(Movies[[#This Row],[studio]]) -> Universal Pictures | G14: Universal Pictures | H14: 5 | I14: =INDEX(financials!B:B,MATCH(VALUE(LEFT(Movies[[#This Row],[movie_id]],3)),financials!A:A,0)) -> 103 | J14: =VLOOKUP(Movies[[#This Row],[movie_id]],financials!A:C,2,FALSE) -> 103 | K14: =INDEX(financials!B:B,MATCH(Movies[[#This Row],[movie_id]],financials!A:A,0)) -> 103 | L14: =INDEX(financials!C:C,MATCH(Movies[[#This Row],[movie_id]],financials!A:A,0)) -> 460.5 | M14: =INDEX(financials!D:D,MATCH(Movies[[#This Row],[movie_id]],financials!A:A,0)) -> Millions | N14: =INDEX(financials!E:E,MATCH(Movies[[#This Row],[movie_id]],financials!A:A,0)) -> USD | P14: =INDEX(Financials[],MATCH(Movies[[#This Row],[movie_id]:[movie_id]],Financials[[movie_id]:[movie_id]],0),MATCH("budget",Financials[#Headers],0)) -> 103 | Q14: =INDEX(Financials[],MATCH(Movies[[#This Row],[movie_id]:[movie_id]],Financials[[movie_id]:[movie_id]],0),MATCH("revenue",Financials[#Headers],0)) -> 460.5 | R14: =INDEX(Financials[],MATCH(Movies[[#This Row],[movie_id]:[movie_id]],Financials[[movie_id]:[movie_id]],0),MATCH("unit",Financials[#Headers],0)) -> Millions | S14: =INDEX(Financials[],MATCH(Movies[[#This Row],[movie_id]:[movie_id]],Financials[[movie_id]:[movie_id]],0),MATCH("currency",Financials[#Headers],0)) -> USD | U14: =INDEX(financials!$A:$D,MATCH(Movies[[#This Row],[movie_id]],financials!$A:$A,0), MATCH("revenue",financials!$1:$1,0)) -> 460.5 | V14: =INDEX(financials!$A:$D,MATCH(Movies[[#This Row],[movie_id]],financials!$A:$A,0), MATCH("budget",financials!$1:$1,0)) -> 103 | W14: =INDEX(financials!$A:$D,MATCH(Movies[[#This Row],[movie_id]],financials!$A:$A,0), MATCH("unit",financials!$1:$1,0)) -> Millions | X14: =INDEX(financials!$A:$D,MATCH(Movies[[#This Row],[movie_id]],financials!$A:$A,0), MATCH("currency",financials!$1:$1,0)) -> #REF! | Y14: =IF(Movies[[#This Row],[unit3]]="Billions",Movies[[#This Row],[budget5]]*1000,Movies[[#This Row],[budget5]]) -> 103 | Z14: =IF(Movies[[#This Row],[unit3]]="Billions",Movies[[#This Row],[revenue3]]*1000,Movies[[#This Row],[revenue3]]) -> 460.5 | AA14: =IF(Movies[[#This Row],[currency2]]="INR",Movies[[#This Row],[budget(mln)]]/92,Movies[[#This Row],[budget(mln)]]) -> 103 | AB14: =IF(Movies[[#This Row],[currency2]]="INR",Movies[[#This Row],[revenue(mln)]]/92,Movies[[#This Row],[revenue(mln)]]) -> 460.5
A15: 117 | B15: Titanic | D15: 1997 | E15: 7.9 | F15: =TRIM(Movies[[#This Row],[studio]]) -> Paramount Pictures | G15: Paramount Pictures | H15: 5 | I15: =INDEX(financials!B:B,MATCH(VALUE(LEFT(Movies[[#This Row],[movie_id]],3)),financials!A:A,0)) -> 200 | J15: =VLOOKUP(Movies[[#This Row],[movie_id]],financials!A:C,2,FALSE) -> 200 | K15: =INDEX(financials!B:B,MATCH(Movies[[#This Row],[movie_id]],financials!A:A,0)) -> 200 | L15: =INDEX(financials!C:C,MATCH(Movies[[#This Row],[movie_id]],financials!A:A,0)) -> 2202 | M15: =INDEX(financials!D:D,MATCH(Movies[[#This Row],[movie_id]],financials!A:A,0)) -> Millions | N15: =INDEX(financials!E:E,MATCH(Movies[[#This Row],[movie_id]],financials!A:A,0)) -> USD | P15: =INDEX(Financials[],MATCH(Movies[[#This Row],[movie_id]:[movie_id]],Financials[[movie_id]:[movie_id]],0),MATCH("budget",Financials[#Headers],0)) -> 200 | Q15: =INDEX(Financials[],MATCH(Movies[[#This Row],[movie_id]:[movie_id]],Financials[[movie_id]:[movie_id]],0),MATCH("revenue",Financials[#Headers],0)) -> 2202 | R15: =INDEX(Financials[],MATCH(Movies[[#This Row],[movie_id]:[movie_id]],Financials[[movie_id]:[movie_id]],0),MATCH("unit",Financials[#Headers],0)) -> Millions | S15: =INDEX(Financials[],MATCH(Movies[[#This Row],[movie_id]:[movie_id]],Financials[[movie_id]:[movie_id]],0),MATCH("currency",Financials[#Headers],0)) -> USD | U15: =INDEX(financials!$A:$D,MATCH(Movies[[#This Row],[movie_id]],financials!$A:$A,0), MATCH("revenue",financials!$1:$1,0)) -> 2202 | V15: =INDEX(financials!$A:$D,MATCH(Movies[[#This Row],[movie_id]],financials!$A:$A,0), MATCH("budget",financials!$1:$1,0)) -> 200 | W15: =INDEX(financials!$A:$D,MATCH(Movies[[#This Row],[movie_id]],financials!$A:$A,0), MATCH("unit",financials!$1:$1,0)) -> Millions | X15: =INDEX(financials!$A:$D,MATCH(Movies[[#This Row],[movie_id]],financials!$A:$A,0), MATCH("currency",financials!$1:$1,0)) -> #REF! | Y15: =IF(Movies[[#This Row],[unit3]]="Billions",Movies[[#This Row],[budget5]]*1000,Movies[[#This Row],[budget5]]) -> 200 | Z15: =IF(Movies[[#This Row],[unit3]]="Billions",Movies[[#This Row],[revenue3]]*1000,Movies[[#This Row],[revenue3]]) -> 2202 | AA15: =IF(Movies[[#This Row],[currency2]]="INR",Movies[[#This Row],[budget(mln)]]/92,Movies[[#This Row],[budget(mln)]]) -> 200 | AB15: =IF(Movies[[#This Row],[currency2]]="INR",Movies[[#This Row],[revenue(mln)]]/92,Movies[[#This Row],[revenue(mln)]]) -> 2202
A16: 118 | B16: It's a Wonderful Life | D16: 1946 | E16: 8.6 | F16: =TRIM(Movies[[#This Row],[studio]]) -> Liberty Films | G16: Liberty Films | H16: 5 | I16: =INDEX(financials!B:B,MATCH(VALUE(LEFT(Movies[[#This Row],[movie_id]],3)),financials!A:A,0)) -> 3.18 | J16: =VLOOKUP(Movies[[#This Row],[movie_id]],financials!A:C,2,FALSE) -> 3.18 | K16: =INDEX(financials!B:B,MATCH(Movies[[#This Row],[movie_id]],financials!A:A,0)) -> 3.18 | L16: =INDEX(financials!C:C,MATCH(Movies[[#This Row],[movie_id]],financials!A:A,0)) -> 3.3 | M16: =INDEX(financials!D:D,MATCH(Movies[[#This Row],[movie_id]],financials!A:A,0)) -> Millions | N16: =INDEX(financials!E:E,MATCH(Movies[[#This Row],[movie_id]],financials!A:A,0)) -> USD | P16: =INDEX(Financials[],MATCH(Movies[[#This Row],[movie_id]:[movie_id]],Financials[[movie_id]:[movie_id]],0),MATCH("budget",Financials[#Headers],0)) -> 3.18 | Q16: =INDEX(Financials[],MATCH(Movies[[#This Row],[movie_id]:[movie_id]],Financials[[movie_id]:[movie_id]],0),MATCH("revenue",Financials[#Headers],0)) -> 3.3 | R16: =INDEX(Financials[],MATCH(Movies[[#This Row],[movie_id]:[movie_id]],Financials[[movie_id]:[movie_id]],0),MATCH("unit",Financials[#Headers],0)) -> Millions | S16: =INDEX(Financials[],MATCH(Movies[[#This Row],[movie_id]:[movie_id]],Financials[[movie_id]:[movie_id]],0),MATCH("currency",Financials[#Headers],0)) -> USD | U16: =INDEX(financials!$A:$D,MATCH(Movies[[#This Row],[movie_id]],financials!$A:$A,0), MATCH("revenue",financials!$1:$1,0)) -> 3.3 | V16: =INDEX(financials!$A:$D,MATCH(Movies[[#This Row],[movie_id]],financials!$A:$A,0), MATCH("budget",financials!$1:$1,0)) -> 3.18 | W16: =INDEX(financials!$A:$D,MATCH(Movies[[#This Row],[movie_id]],financials!$A:$A,0), MATCH("unit",financials!$1:$1,0)) -> Millions | X16: =INDEX(financials!$A:$D,MATCH(Movies[[#This Row],[movie_id]],financials!$A:$A,0), MATCH("currency",financials!$1:$1,0)) -> #REF! | Y16: =IF(Movies[[#This Row],[unit3]]="Billions",Movies[[#This Row],[budget5]]*1000,Movies[[#This Row],[budget5]]) -> 3.18 | Z16: =IF(Movies[[#This Row],[unit3]]="Billions",Movies[[#This Row],[revenue3]]*1000,Movies[[#This Row],[revenue3]]) -> 3.3 | AA16: =IF(Movies[[#This Row],[currency2]]="INR",Movies[[#This Row],[budget(mln)]]/92,Movies[[#This Row],[budget(mln)]]) -> 3.18 | AB16: =IF(Movies[[#This Row],[currency2]]="INR",Movies[[#This Row],[revenue(mln)]]/92,Movies[[#This Row],[revenue(mln)]]) -> 3.3
A17: 119 | B17: Avatar | D17: 2009 | E17: 7.8 | F17: =TRIM(Movies[[#This Row],[studio]]) -> 20th Century Fox | G17: 20th Century Fox | H17: 5 | I17: =INDEX(financials!B:B,MATCH(VALUE(LEFT(Movies[[#This Row],[movie_id]],3)),financials!A:A,0)) -> 237 | J17: =VLOOKUP(Movies[[#This Row],[movie_id]],financials!A:C,2,FALSE) -> 237 | K17: =INDEX(financials!B:B,MATCH(Movies[[#This Row],[movie_id]],financials!A:A,0)) -> 237 | L17: =INDEX(financials!C:C,MATCH(Movies[[#This Row],[movie_id]],financials!A:A,0)) -> 2847 | M17: =INDEX(financials!D:D,MATCH(Movies[[#This Row],[movie_id]],financials!A:A,0)) -> Millions | N17: =INDEX(financials!E:E,MATCH(Movies[[#This Row],[movie_id]],financials!A:A,0)) -> USD | P17: =INDEX(Financials[],MATCH(Movies[[#This Row],[movie_id]:[movie_id]],Financials[[movie_id]:[movie_id]],0),MATCH("budget",Financials[#Headers],0)) -> 237 | Q17: =INDEX(Financials[],MATCH(Movies[[#This Row],[movie_id]:[movie_id]],Financials[[movie_id]:[movie_id]],0),MATCH("revenue",Financials[#Headers],0)) -> 2847 | R17: =INDEX(Financials[],MATCH(Movies[[#This Row],[movie_id]:[movie_id]],Financials[[movie_id]:[movie_id]],0),MATCH("unit",Financials[#Headers],0)) -> Millions | S17: =INDEX(Financials[],MATCH(Movies[[#This Row],[movie_id]:[movie_id]],Financials[[movie_id]:[movie_id]],0),MATCH("currency",Financials[#Headers],0)) -> USD | U17: =INDEX(financials!$A:$D,MATCH(Movies[[#This Row],[movie_id]],financials!$A:$A,0), MATCH("revenue",financials!$1:$1,0)) -> 2847 | V17: =INDEX(financials!$A:$D,MATCH(Movies[[#This Row],[movie_id]],financials!$A:$A,0), MATCH("budget",financials!$1:$1,0)) -> 237 | W17: =INDEX(financials!$A:$D,MATCH(Movies[[#This Row],[movie_id]],financials!$A:$A,0), MATCH("unit",financials!$1:$1,0)) -> Millions | X17: =INDEX(financials!$A:$D,MATCH(Movies[[#This Row],[movie_id]],financials!$A:$A,0), MATCH("currency",financials!$1:$1,0)) -> #REF! | Y17: =IF(Movies[[#This Row],[unit3]]="Billions",Movies[[#This Row],[budget5]]*1000,Movies[[#This Row],[budget5]]) -> 237 | Z17: =IF(Movies[[#This Row],[unit3]]="Billions",Movies[[#This Row],[revenue3]]*1000,Movies[[#This Row],[revenue3]]) -> 2847 | AA17: =IF(Movies[[#This Row],[currency2]]="INR",Movies[[#This Row],[budget(mln)]]/92,Movies[[#This Row],[budget(mln)]]) -> 237 | AB17: =IF(Movies[[#This Row],[currency2]]="INR",Movies[[#This Row],[revenue(mln)]]/92,Movies[[#This Row],[revenue(mln)]]) -> 2847
A18: 120 | B18: The Godfather | D18: 1972 | E18: 9.2 | F18: =TRIM(Movies[[#This Row],[studio]]) -> Paramount Pictures | G18: Paramount Pictures | H18: 5 | I18: =INDEX(financials!B:B,MATCH(VALUE(LEFT(Movies[[#This Row],[movie_id]],3)),financials!A:A,0)) -> 7.2 | J18: =VLOOKUP(Movies[[#This Row],[movie_id]],financials!A:C,2,FALSE) -> 7.2 | K18: =INDEX(financials!B:B,MATCH(Movies[[#This Row],[movie_id]],financials!A:A,0)) -> 7.2 | L18: =INDEX(financials!C:C,MATCH(Movies[[#This Row],[movie_id]],financials!A:A,0)) -> 291 | M18: =INDEX(financials!D:D,MATCH(Movies[[#This Row],[movie_id]],financials!A:A,0)) -> Millions | N18: =INDEX(financials!E:E,MATCH(Movies[[#This Row],[movie_id]],financials!A:A,0)) -> USD | P18: =INDEX(Financials[],MATCH(Movies[[#This Row],[movie_id]:[movie_id]],Financials[[movie_id]:[movie_id]],0),MATCH("budget",Financials[#Headers],0)) -> 7.2 | Q18: =INDEX(Financials[],MATCH(Movies[[#This Row],[movie_id]:[movie_id]],Financials[[movie_id]:[movie_id]],0),MATCH("revenue",Financials[#Headers],0)) -> 291 | R18: =INDEX(Financials[],MATCH(Movies[[#This Row],[movie_id]:[movie_id]],Financials[[movie_id]:[movie_id]],0),MATCH("unit",Financials[#Headers],0)) -> Millions | S18: =INDEX(Financials[],MATCH(Movies[[#This Row],[movie_id]:[movie_id]],Financials[[movie_id]:[movie_id]],0),MATCH("currency",Financials[#Headers],0)) -> USD | U18: =INDEX(financials!$A:$D,MATCH(Movies[[#This Row],[movie_id]],financials!$A:$A,0), MATCH("revenue",financials!$1:$1,0)) -> 291 | V18: =INDEX(financials!$A:$D,MATCH(Movies[[#This Row],[movie_id]],financials!$A:$A,0), MATCH("budget",financials!$1:$1,0)) -> 7.2 | W18: =INDEX(financials!$A:$D,MATCH(Movies[[#This Row],[movie_id]],financials!$A:$A,0), MATCH("unit",financials!$1:$1,0)) -> Millions | X18: =INDEX(financials!$A:$D,MATCH(Movies[[#This Row],[movie_id]],financials!$A:$A,0), MATCH("currency",financials!$1:$1,0)) -> #REF! | Y18: =IF(Movies[[#This Row],[unit3]]="Billions",Movies[[#This Row],[budget5]]*1000,Movies[[#This Row],[budget5]]) -> 7.2 | Z18: =IF(Movies[[#This Row],[unit3]]="Billions",Movies[[#This Row],[revenue3]]*1000,Movies[[#This Row],[revenue3]]) -> 291 | AA18: =IF(Movies[[#This Row],[currency2]]="INR",Movies[[#This Row],[budget(mln)]]/92,Movies[[#This Row],[budget(mln)]]) -> 7.2 | AB18: =IF(Movies[[#This Row],[currency2]]="INR",Movies[[#This Row],[revenue(mln)]]/92,Movies[[#This Row],[revenue(mln)]]) -> 291
A19: 121 | B19: The Dark Knight | D19: 2008 | E19: 9 | F19: =TRIM(Movies[[#This Row],[studio]]) -> Syncopy | G19: Syncopy | H19: 5 | I19: =INDEX(financials!B:B,MATCH(VALUE(LEFT(Movies[[#This Row],[movie_id]],3)),financials!A:A,0)) -> 185 | J19: =VLOOKUP(Movies[[#This Row],[movie_id]],financials!A:C,2,FALSE) -> 185 | K19: =INDEX(financials!B:B,MATCH(Movies[[#This Row],[movie_id]],financials!A:A,0)) -> 185 | L19: =INDEX(financials!C:C,MATCH(Movies[[#This Row],[movie_id]],financials!A:A,0)) -> 1006 | M19: =INDEX(financials!D:D,MATCH(Movies[[#This Row],[movie_id]],financials!A:A,0)) -> Millions | N19: =INDEX(financials!E:E,MATCH(Movies[[#This Row],[movie_id]],financials!A:A,0)) -> USD | P19: =INDEX(Financials[],MATCH(Movies[[#This Row],[movie_id]:[movie_id]],Financials[[movie_id]:[movie_id]],0),MATCH("budget",Financials[#Headers],0)) -> 185 | Q19: =INDEX(Financials[],MATCH(Movies[[#This Row],[movie_id]:[movie_id]],Financials[[movie_id]:[movie_id]],0),MATCH("revenue",Financials[#Headers],0)) -> 1006 | R19: =INDEX(Financials[],MATCH(Movies[[#This Row],[movie_id]:[movie_id]],Financials[[movie_id]:[movie_id]],0),MATCH("unit",Financials[#Headers],0)) -> Millions | S19: =INDEX(Financials[],MATCH(Movies[[#This Row],[movie_id]:[movie_id]],Financials[[movie_id]:[movie_id]],0),MATCH("currency",Financials[#Headers],0)) -> USD | U19: =INDEX(financials!$A:$D,MATCH(Movies[[#This Row],[movie_id]],financials!$A:$A,0), MATCH("revenue",financials!$1:$1,0)) -> 1006 | V19: =INDEX(financials!$A:$D,MATCH(Movies[[#This Row],[movie_id]],financials!$A:$A,0), MATCH("budget",financials!$1:$1,0)) -> 185 | W19: =INDEX(financials!$A:$D,MATCH(Movies[[#This Row],[movie_id]],financials!$A:$A,0), MATCH("unit",financials!$1:$1,0)) -> Millions | X19: =INDEX(financials!$A:$D,MATCH(Movies[[#This Row],[movie_id]],financials!$A:$A,0), MATCH("currency",financials!$1:$1,0)) -> #REF! | Y19: =IF(Movies[[#This Row],[unit3]]="Billions",Movies[[#This Row],[budget5]]*1000,Movies[[#This Row],[budget5]]) -> 185 | Z19: =IF(Movies[[#This Row],[unit3]]="Billions",Movies[[#This Row],[revenue3]]*1000,Movies[[#This Row],[revenue3]]) -> 1006 | AA19: =IF(Movies[[#This Row],[currency2]]="INR",Movies[[#This Row],[budget(mln)]]/92,Movies[[#This Row],[budget(mln)]]) -> 185 | AB19: =IF(Movies[[#This Row],[currency2]]="INR",Movies[[#This Row],[revenue(mln)]]/92,Movies[[#This Row],[revenue(mln)]]) -> 1006
A20: 122 | B20: Schindler's List | D20: 1993 | E20: 9 | F20: =TRIM(Movies[[#This Row],[studio]]) -> Universal Pictures | G20: Universal Pictures | H20: 5 | I20: =INDEX(financials!B:B,MATCH(VALUE(LEFT(Movies[[#This Row],[movie_id]],3)),financials!A:A,0)) -> 22 | J20: =VLOOKUP(Movies[[#This Row],[movie_id]],financials!A:C,2,FALSE) -> 22 | K20: =INDEX(financials!B:B,MATCH(Movies[[#This Row],[movie_id]],financials!A:A,0)) -> 22 | L20: =INDEX(financials!C:C,MATCH(Movies[[#This Row],[movie_id]],financials!A:A,0)) -> 322.2 | M20: =INDEX(financials!D:D,MATCH(Movies[[#This Row],[movie_id]],financials!A:A,0)) -> Millions | N20: =INDEX(financials!E:E,MATCH(Movies[[#This Row],[movie_id]],financials!A:A,0)) -> USD | P20: =INDEX(Financials[],MATCH(Movies[[#This Row],[movie_id]:[movie_id]],Financials[[movie_id]:[movie_id]],0),MATCH("budget",Financials[#Headers],0)) -> 22 | Q20: =INDEX(Financials[],MATCH(Movies[[#This Row],[movie_id]:[movie_id]],Financials[[movie_id]:[movie_id]],0),MATCH("revenue",Financials[#Headers],0)) -> 322.2 | R20: =INDEX(Financials[],MATCH(Movies[[#This Row],[movie_id]:[movie_id]],Financials[[movie_id]:[movie_id]],0),MATCH("unit",Financials[#Headers],0)) -> Millions | S20: =INDEX(Financials[],MATCH(Movies[[#This Row],[movie_id]:[movie_id]],Financials[[movie_id]:[movie_id]],0),MATCH("currency",Financials[#Headers],0)) -> USD | U20: =INDEX(financials!$A:$D,MATCH(Movies[[#This Row],[movie_id]],financials!$A:$A,0), MATCH("revenue",financials!$1:$1,0)) -> 322.2 | V20: =INDEX(financials!$A:$D,MATCH(Movies[[#This Row],[movie_id]],financials!$A:$A,0), MATCH("budget",financials!$1:$1,0)) -> 22 | W20: =INDEX(financials!$A:$D,MATCH(Movies[[#This Row],[movie_id]],financials!$A:$A,0), MATCH("unit",financials!$1:$1,0)) -> Millions | X20: =INDEX(financials!$A:$D,MATCH(Movies[[#This Row],[movie_id]],financials!$A:$A,0), MATCH("currency",financials!$1:$1,0)) -> #REF! | Y20: =IF(Movies[[#This Row],[unit3]]="Billions",Movies[[#This Row],[budget5]]*1000,Movies[[#This Row],[budget5]]) -> 22 | Z20: =IF(Movies[[#This Row],[unit3]]="Billions",Movies[[#This Row],[revenue3]]*1000,Movies[[#This Row],[revenue3]]) -> 322.2 | AA20: =IF(Movies[[#This Row],[currency2]]="INR",Movies[[#This Row],[budget(mln)]]/92,Movies[[#This Row],[budget(mln)]]) -> 22 | AB20: =IF(Movies[[#This Row],[currency2]]="INR",Movies[[#This Row],[revenue(mln)]]/92,Movies[[#This Row],[revenue(mln)]]) -> 322.2
A21: 123 | B21: Jurassic Park | D21: 1993 | E21: 8.2 | F21: =TRIM(Movies[[#This Row],[studio]]) -> Universal Pictures | G21: Universal Pictures | H21: 5 | I21: =INDEX(financials!B:B,MATCH(VALUE(LEFT(Movies[[#This Row],[movie_id]],3)),financials!A:A,0)) -> 63 | J21: =VLOOKUP(Movies[[#This Row],[movie_id]],financials!A:C,2,FALSE) -> 63 | K21: =INDEX(financials!B:B,MATCH(Movies[[#This Row],[movie_id]],financials!A:A,0)) -> 63 | L21: =INDEX(financials!C:C,MATCH(Movies[[#This Row],[movie_id]],financials!A:A,0)) -> 1046 | M21: =INDEX(financials!D:D,MATCH(Movies[[#This Row],[movie_id]],financials!A:A,0)) -> Millions | N21: =INDEX(financials!E:E,MATCH(Movies[[#This Row],[movie_id]],financials!A:A,0)) -> USD | P21: =INDEX(Financials[],MATCH(Movies[[#This Row],[movie_id]:[movie_id]],Financials[[movie_id]:[movie_id]],0),MATCH("budget",Financials[#Headers],0)) -> 63 | Q21: =INDEX(Financials[],MATCH(Movies[[#This Row],[movie_id]:[movie_id]],Financials[[movie_id]:[movie_id]],0),MATCH("revenue",Financials[#Headers],0)) -> 1046 | R21: =INDEX(Financials[],MATCH(Movies[[#This Row],[movie_id]:[movie_id]],Financials[[movie_id]:[movie_id]],0),MATCH("unit",Financials[#Headers],0)) -> Millions | S21: =INDEX(Financials[],MATCH(Movies[[#This Row],[movie_id]:[movie_id]],Financials[[movie_id]:[movie_id]],0),MATCH("currency",Financials[#Headers],0)) -> USD | U21: =INDEX(financials!$A:$D,MATCH(Movies[[#This Row],[movie_id]],financials!$A:$A,0), MATCH("revenue",financials!$1:$1,0)) -> 1046 | V21: =INDEX(financials!$A:$D,MATCH(Movies[[#This Row],[movie_id]],financials!$A:$A,0), MATCH("budget",financials!$1:$1,0)) -> 63 | W21: =INDEX(financials!$A:$D,MATCH(Movies[[#This Row],[movie_id]],financials!$A:$A,0), MATCH("unit",financials!$1:$1,0)) -> Millions | X21: =INDEX(financials!$A:$D,MATCH(Movies[[#This Row],[movie_id]],financials!$A:$A,0), MATCH("currency",financials!$1:$1,0)) -> #REF! | Y21: =IF(Movies[[#This Row],[unit3]]="Billions",Movies[[#This Row],[budget5]]*1000,Movies[[#This Row],[budget5]]) -> 63 | Z21: =IF(Movies[[#This Row],[unit3]]="Billions",Movies[[#This Row],[revenue3]]*1000,Movies[[#This Row],[revenue3]]) -> 1046 | AA21: =IF(Movies[[#This Row],[currency2]]="INR",Movies[[#This Row],[budget(mln)]]/92,Movies[[#This Row],[budget(mln)]]) -> 63 | AB21: =IF(Movies[[#This Row],[currency2]]="INR",Movies[[#This Row],[revenue(mln)]]/92,Movies[[#This Row],[revenue(mln)]]) -> 1046
A22: 124 | B22: Parasite | D22: 2019 | E22: 8.5 | F22: =TRIM(Movies[[#This Row],[studio]]) | H22: 5 | I22: =INDEX(financials!B:B,MATCH(VALUE(LEFT(Movies[[#This Row],[movie_id]],3)),financials!A:A,0)) -> 15.5 | J22: =VLOOKUP(Movies[[#This Row],[movie_id]],financials!A:C,2,FALSE) -> 15.5 | K22: =INDEX(financials!B:B,MATCH(Movies[[#This Row],[movie_id]],financials!A:A,0)) -> 15.5 | L22: =INDEX(financials!C:C,MATCH(Movies[[#This Row],[movie_id]],financials!A:A,0)) -> 263.1 | M22: =INDEX(financials!D:D,MATCH(Movies[[#This Row],[movie_id]],financials!A:A,0)) -> Millions | N22: =INDEX(financials!E:E,MATCH(Movies[[#This Row],[movie_id]],financials!A:A,0)) -> USD | P22: =INDEX(Financials[],MATCH(Movies[[#This Row],[movie_id]:[movie_id]],Financials[[movie_id]:[movie_id]],0),MATCH("budget",Financials[#Headers],0)) -> 15.5 | Q22: =INDEX(Financials[],MATCH(Movies[[#This Row],[movie_id]:[movie_id]],Financials[[movie_id]:[movie_id]],0),MATCH("revenue",Financials[#Headers],0)) -> 263.1 | R22: =INDEX(Financials[],MATCH(Movies[[#This Row],[movie_id]:[movie_id]],Financials[[movie_id]:[movie_id]],0),MATCH("unit",Financials[#Headers],0)) -> Millions | S22: =INDEX(Financials[],MATCH(Movies[[#This Row],[movie_id]:[movie_id]],Financials[[movie_id]:[movie_id]],0),MATCH("currency",Financials[#Headers],0)) -> USD | U22: =INDEX(financials!$A:$D,MATCH(Movies[[#This Row],[movie_id]],financials!$A:$A,0), MATCH("revenue",financials!$1:$1,0)) -> 263.1 | V22: =INDEX(financials!$A:$D,MATCH(Movies[[#This Row],[movie_id]],financials!$A:$A,0), MATCH("budget",financials!$1:$1,0)) -> 15.5 | W22: =INDEX(financials!$A:$D,MATCH(Movies[[#This Row],[movie_id]],financials!$A:$A,0), MATCH("unit",financials!$1:$1,0)) -> Millions | X22: =INDEX(financials!$A:$D,MATCH(Movies[[#This Row],[movie_id]],financials!$A:$A,0), MATCH("currency",financials!$1:$1,0)) -> #REF! | Y22: =IF(Movies[[#This Row],[unit3]]="Billions",Movies[[#This Row],[budget5]]*1000,Movies[[#This Row],[budget5]]) -> 15.5 | Z22: =IF(Movies[[#This Row],[unit3]]="Billions",Movies[[#This Row],[revenue3]]*1000,Movies[[#This Row],[revenue3]]) -> 263.1 | AA22: =IF(Movies[[#This Row],[currency2]]="INR",Movies[[#This Row],[budget(mln)]]/92,Movies[[#This Row],[budget(mln)]]) -> 15.5 | AB22: =IF(Movies[[#This Row],[currency2]]="INR",Movies[[#This Row],[revenue(mln)]]/92,Movies[[#This Row],[revenue(mln)]]) -> 263.1
A23: 125 | B23: Avengers | C23: Endgame | D23: 2019 | E23: 8.4 | F23: =TRIM(Movies[[#This Row],[studio]]) -> Marvel Studios | G23: Marvel Studios | H23: 5 | I23: =INDEX(financials!B:B,MATCH(VALUE(LEFT(Movies[[#This Row],[movie_id]],3)),financials!A:A,0)) -> 400 | J23: =VLOOKUP(Movies[[#This Row],[movie_id]],financials!A:C,2,FALSE) -> 400 | K23: =INDEX(financials!B:B,MATCH(Movies[[#This Row],[movie_id]],financials!A:A,0)) -> 400 | L23: =INDEX(financials!C:C,MATCH(Movies[[#This Row],[movie_id]],financials!A:A,0)) -> 2798 | M23: =INDEX(financials!D:D,MATCH(Movies[[#This Row],[movie_id]],financials!A:A,0)) -> Millions | N23: =INDEX(financials!E:E,MATCH(Movies[[#This Row],[movie_id]],financials!A:A,0)) -> USD | P23: =INDEX(Financials[],MATCH(Movies[[#This Row],[movie_id]:[movie_id]],Financials[[movie_id]:[movie_id]],0),MATCH("budget",Financials[#Headers],0)) -> 400 | Q23: =INDEX(Financials[],MATCH(Movies[[#This Row],[movie_id]:[movie_id]],Financials[[movie_id]:[movie_id]],0),MATCH("revenue",Financials[#Headers],0)) -> 2798 | R23: =INDEX(Financials[],MATCH(Movies[[#This Row],[movie_id]:[movie_id]],Financials[[movie_id]:[movie_id]],0),MATCH("unit",Financials[#Headers],0)) -> Millions | S23: =INDEX(Financials[],MATCH(Movies[[#This Row],[movie_id]:[movie_id]],Financials[[movie_id]:[movie_id]],0),MATCH("currency",Financials[#Headers],0)) -> USD | U23: =INDEX(financials!$A:$D,MATCH(Movies[[#This Row],[movie_id]],financials!$A:$A,0), MATCH("revenue",financials!$1:$1,0)) -> 2798 | V23: =INDEX(financials!$A:$D,MATCH(Movies[[#This Row],[movie_id]],financials!$A:$A,0), MATCH("budget",financials!$1:$1,0)) -> 400 | W23: =INDEX(financials!$A:$D,MATCH(Movies[[#This Row],[movie_id]],financials!$A:$A,0), MATCH("unit",financials!$1:$1,0)) -> Millions | X23: =INDEX(financials!$A:$D,MATCH(Movies[[#This Row],[movie_id]],financials!$A:$A,0), MATCH("currency",financials!$1:$1,0)) -> #REF! | Y23: =IF(Movies[[#This Row],[unit3]]="Billions",Movies[[#This Row],[budget5]]*1000,Movies[[#This Row],[budget5]]) -> 400 | Z23: =IF(Movies[[#This Row],[unit3]]="Billions",Movies[[#This Row],[revenue3]]*1000,Movies[[#This Row],[revenue3]]) -> 2798 | AA23: =IF(Movies[[#This Row],[currency2]]="INR",Movies[[#This Row],[budget(mln)]]/92,Movies[[#This Row],[budget(mln)]]) -> 400 | AB23: =IF(Movies[[#This Row],[currency2]]="INR",Movies[[#This Row],[revenue(mln)]]/92,Movies[[#This Row],[revenue(mln)]]) -> 2798
A24: 126 | B24: Avengers | C24: Infinity War | D24: 2018 | E24: 8.4 | F24: =TRIM(Movies[[#This Row],[studio]]) -> Marvel Studios | G24: Marvel Studios | H24: 5 | I24: =INDEX(financials!B:B,MATCH(VALUE(LEFT(Movies[[#This Row],[movie_id]],3)),financials!A:A,0)) -> 400 | J24: =VLOOKUP(Movies[[#This Row],[movie_id]],financials!A:C,2,FALSE) -> 400 | K24: =INDEX(financials!B:B,MATCH(Movies[[#This Row],[movie_id]],financials!A:A,0)) -> 400 | L24: =INDEX(financials!C:C,MATCH(Movies[[#This Row],[movie_id]],financials!A:A,0)) -> 2048 | M24: =INDEX(financials!D:D,MATCH(Movies[[#This Row],[movie_id]],financials!A:A,0)) -> Millions | N24: =INDEX(financials!E:E,MATCH(Movies[[#This Row],[movie_id]],financials!A:A,0)) -> USD | P24: =INDEX(Financials[],MATCH(Movies[[#This Row],[movie_id]:[movie_id]],Financials[[movie_id]:[movie_id]],0),MATCH("budget",Financials[#Headers],0)) -> 400 | Q24: =INDEX(Financials[],MATCH(Movies[[#This Row],[movie_id]:[movie_id]],Financials[[movie_id]:[movie_id]],0),MATCH("revenue",Financials[#Headers],0)) -> 2048 | R24: =INDEX(Financials[],MATCH(Movies[[#This Row],[movie_id]:[movie_id]],Financials[[movie_id]:[movie_id]],0),MATCH("unit",Financials[#Headers],0)) -> Millions | S24: =INDEX(Financials[],MATCH(Movies[[#This Row],[movie_id]:[movie_id]],Financials[[movie_id]:[movie_id]],0),MATCH("currency",Financials[#Headers],0)) -> USD | U24: =INDEX(financials!$A:$D,MATCH(Movies[[#This Row],[movie_id]],financials!$A:$A,0), MATCH("revenue",financials!$1:$1,0)) -> 2048 | V24: =INDEX(financials!$A:$D,MATCH(Movies[[#This Row],[movie_id]],financials!$A:$A,0), MATCH("budget",financials!$1:$1,0)) -> 400 | W24: =INDEX(financials!$A:$D,MATCH(Movies[[#This Row],[movie_id]],financials!$A:$A,0), MATCH("unit",financials!$1:$1,0)) -> Millions | X24: =INDEX(financials!$A:$D,MATCH(Movies[[#This Row],[movie_id]],financials!$A:$A,0), MATCH("currency",financials!$1:$1,0)) -> #REF! | Y24: =IF(Movies[[#This Row],[unit3]]="Billions",Movies[[#This Row],[budget5]]*1000,Movies[[#This Row],[budget5]]) -> 400 | Z24: =IF(Movies[[#This Row],[unit3]]="Billions",Movies[[#This Row],[revenue3]]*1000,Movies[[#This Row],[revenue3]]) -> 2048 | AA24: =IF(Movies[[#This Row],[currency2]]="INR",Movies[[#This Row],[budget(mln)]]/92,Movies[[#This Row],[budget(mln)]]) -> 400 | AB24: =IF(Movies[[#This Row],[currency2]]="INR",Movies[[#This Row],[revenue(mln)]]/92,Movies[[#This Row],[revenue(mln)]]) -> 2048
A25: 127 | B25: Pather Panchali | D25: 1955 | E25: 8.3 | F25: =TRIM(Movies[[#This Row],[studio]]) -> Government of West Bengal | G25: Government of West Bengal | H25: 7 | I25: =INDEX(financials!B:B,MATCH(VALUE(LEFT(Movies[[#This Row],[movie_id]],3)),financials!A:A,0)) -> 70 | J25: =VLOOKUP(Movies[[#This Row],[movie_id]],financials!A:C,2,FALSE) -> 70 | K25: =INDEX(financials!B:B,MATCH(Movies[[#This Row],[movie_id]],financials!A:A,0)) -> 70 | L25: =INDEX(financials!C:C,MATCH(Movies[[#This Row],[movie_id]],financials!A:A,0)) -> 100 | M25: =INDEX(financials!D:D,MATCH(Movies[[#This Row],[movie_id]],financials!A:A,0)) -> Millions | N25: =INDEX(financials!E:E,MATCH(Movies[[#This Row],[movie_id]],financials!A:A,0)) -> INR | P25: =INDEX(Financials[],MATCH(Movies[[#This Row],[movie_id]:[movie_id]],Financials[[movie_id]:[movie_id]],0),MATCH("budget",Financials[#Headers],0)) -> 70 | Q25: =INDEX(Financials[],MATCH(Movies[[#This Row],[movie_id]:[movie_id]],Financials[[movie_id]:[movie_id]],0),MATCH("revenue",Financials[#Headers],0)) -> 100 | R25: =INDEX(Financials[],MATCH(Movies[[#This Row],[movie_id]:[movie_id]],Financials[[movie_id]:[movie_id]],0),MATCH("unit",Financials[#Headers],0)) -> Millions | S25: =INDEX(Financials[],MATCH(Movies[[#This Row],[movie_id]:[movie_id]],Financials[[movie_id]:[movie_id]],0),MATCH("currency",Financials[#Headers],0)) -> INR | U25: =INDEX(financials!$A:$D,MATCH(Movies[[#This Row],[movie_id]],financials!$A:$A,0), MATCH("revenue",financials!$1:$1,0)) -> 100 | V25: =INDEX(financials!$A:$D,MATCH(Movies[[#This Row],[movie_id]],financials!$A:$A,0), MATCH("budget",financials!$1:$1,0)) -> 70 | W25: =INDEX(financials!$A:$D,MATCH(Movies[[#This Row],[movie_id]],financials!$A:$A,0), MATCH("unit",financials!$1:$1,0)) -> Millions | X25: =INDEX(financials!$A:$D,MATCH(Movies[[#This Row],[movie_id]],financials!$A:$A,0), MATCH("currency",financials!$1:$1,0)) -> #REF! | Y25: =IF(Movies[[#This Row],[unit3]]="Billions",Movies[[#This Row],[budget5]]*1000,Movies[[#This Row],[budget5]]) -> 70 | Z25: =IF(Movies[[#This Row],[unit3]]="Billions",Movies[[#This Row],[revenue3]]*1000,Movies[[#This Row],[revenue3]]) -> 100 | AA25: =IF(Movies[[#This Row],[currency2]]="INR",Movies[[#This Row],[budget(mln)]]/92,Movies[[#This Row],[budget(mln)]]) -> 0.76086957 | AB25: =IF(Movies[[#This Row],[currency2]]="INR",Movies[[#This Row],[revenue(mln)]]/92,Movies[[#This Row],[revenue(mln)]]) -> 1.0869565
